Workbook

Sheet Planilha1
A1: ID | B1: camera | C1: patrimonio | D1: sd | E1: data_instalacao | F1: hora_instalacao | G1: bateria_inicio | H1: data_retirada | I1: hora_retirada | J1: bateria_fim | K1: n_fotos | L1: vegetacao | M1: altura_media_veg | N1: lat | O1: long | P1: observacoes | Q1: mamiferos | R1: agricultura_3000m | S1: cana_3000m | T1: floresta_3000m | U1: pastagem_3000m | V1: veg_herb_3000m | W1: ndvi_vegnativa_3000m | X1: ndvi_cana_3000 | Y1: enn_mn_3000
A2: P003 | B2: C1 | C2: 059.028589 | D2: 7A | E2: 42895 | F2: 0.49027778 | G2: 99 | H2: 42922 | I2: 0.33541667 | J2: 68 | K2: 252 | L2: app | M2: 9 | N2: 21.40782 | O2: 048.71703 | P2: transição de mata mesófila para cerrado / muito cipó / mais mesófila que cerrado / presença de apiário | Q2: foçados de tatus | R2: =VLOOKUP(A2,comp!A:F,2,FALSE) -> 29.234672 | S2: =VLOOKUP(A2,comp!A:F,3,FALSE) -> 58.883721 | T2: =VLOOKUP(A2,comp!A:F,4,FALSE) -> 9.5870331 | U2: =VLOOKUP(A2,comp!A:F,5,FALSE) -> 1.9281184 | V2: =VLOOKUP(A2,comp!A:F,6,FALSE) -> 0.10147992 | W2: =VLOOKUP(A2,ndvi_vegnativa!A:F,2,FALSE) -> 0.8295516 | X2: =VLOOKUP(A2,ndvi_cana!A:F,2,FALSE) -> 0.50019547 | Y2: =VLOOKUP(A2,fragmentos!A:F,2,FALSE) -> 148.78106
A3: P003 | B3: C2 | C3: 059.028606 | D3: 8A | E3: 42895 | F3: 0.53333333 | G3: 99 | H3: 42922 | I3: 0.35277778 | J3: 68 | K3: 426 | L3: app | M3: 9 | N3: 21.40922 | O3: 048.71751 | P3: muito fechado com cipó / impossível andar / em regeneracao | Q3: rastro de Cuniculus paca | R3: =VLOOKUP(A3,comp!A:F,2,FALSE) -> 29.234672 | S3: =VLOOKUP(A3,comp!A:F,3,FALSE) -> 58.883721 | T3: =VLOOKUP(A3,comp!A:F,4,FALSE) -> 9.5870331 | U3: =VLOOKUP(A3,comp!A:F,5,FALSE) -> 1.9281184 | V3: =VLOOKUP(A3,comp!A:F,6,FALSE) -> 0.10147992 | W3: =VLOOKUP(A3,ndvi_vegnativa!A:F,2,FALSE) -> 0.8295516 | X3: =VLOOKUP(A3,ndvi_cana!A:F,2,FALSE) -> 0.50019547 | Y3: =VLOOKUP(A3,fragmentos!A:F,2,FALSE) -> 148.78106
A4: P003 | B4: C3 | C4: 059.028602 | D4: 9A | E4: 42895 | F4: 0.55486111 | G4: 99 | H4: 42922 | I4: 0.36388889 | J4: 83 | K4: 329 | L4: capoeira | M4: 6 | N4: 21.40947 | O4: 048.71638 | P4: árvores distantes / ambiente aberto mais semelhante à estacional semidecidual / mata em regenereção | Q4: rastro de cachorro | R4: =VLOOKUP(A4,comp!A:F,2,FALSE) -> 29.234672 | S4: =VLOOKUP(A4,comp!A:F,3,FALSE) -> 58.883721 | T4: =VLOOKUP(A4,comp!A:F,4,FALSE) -> 9.5870331 | U4: =VLOOKUP(A4,comp!A:F,5,FALSE) -> 1.9281184 | V4: =VLOOKUP(A4,comp!A:F,6,FALSE) -> 0.10147992 | W4: =VLOOKUP(A4,ndvi_vegnativa!A:F,2,FALSE) -> 0.8295516 | X4: =VLOOKUP(A4,ndvi_cana!A:F,2,FALSE) -> 0.50019547 | Y4: =VLOOKUP(A4,fragmentos!A:F,2,FALSE) -> 148.78106
A5: P006 | B5: C1 | C5: 059028601 | D5: 10B | E5: 43354 | F5: 0.49652778 | G5: 95 | H5: 43397 | I5: 0.46319444 | J5: NA | K5: 83 | L5: decidua | M5: 19 | N5: 21.08277 | O5: 047.59609 | P5: alto de morro, muito seco, muita pedra. Caraguatá, caixa de abelha perto | R5: =VLOOKUP(A5,comp!A:F,2,FALSE) -> 18.718462 | S5: =VLOOKUP(A5,comp!A:F,3,FALSE) -> 62.946466 | T5: =VLOOKUP(A5,comp!A:F,4,FALSE) -> 10.261326 | U5: =VLOOKUP(A5,comp!A:F,5,FALSE) -> 7.932794 | V5: =VLOOKUP(A5,comp!A:F,6,FALSE) -> 0.064838046 | W5: =VLOOKUP(A5,ndvi_vegnativa!A:F,2,FALSE) -> 0.7741789 | X5: =VLOOKUP(A5,ndvi_cana!A:F,2,FALSE) -> 0.58468119 | Y5: =VLOOKUP(A5,fragmentos!A:F,2,FALSE) -> 154.97493
A6: P006 | B6: C2 | C6: 059028602 | D6: 2B | E6: 43354 | F6: 0.59652778 | G6: 97 | H6: 43397 | I6: 0.49375 | J6: NA | K6: 465 | L6: app | M6: 19 | N6: 21.09046 | O6: 047.59980 | P6: solo úmido com "gengibre" | R6: =VLOOKUP(A6,comp!A:F,2,FALSE) -> 18.718462 | S6: =VLOOKUP(A6,comp!A:F,3,FALSE) -> 62.946466 | T6: =VLOOKUP(A6,comp!A:F,4,FALSE) -> 10.261326 | U6: =VLOOKUP(A6,comp!A:F,5,FALSE) -> 7.932794 | V6: =VLOOKUP(A6,comp!A:F,6,FALSE) -> 0.064838046 | W6: =VLOOKUP(A6,ndvi_vegnativa!A:F,2,FALSE) -> 0.7741789 | X6: =VLOOKUP(A6,ndvi_cana!A:F,2,FALSE) -> 0.58468119 | Y6: =VLOOKUP(A6,fragmentos!A:F,2,FALSE) -> 154.97493
A7: P006 | B7: C3 | C7: 059028587 | D7: 1B | E7: 43354 | F7: 0.62013889 | G7: 96 | H7: 43397 | I7: 0.48194444 | J7: NA | K7: 183 | L7: app | M7: 19 | N7: 21.08933 | O7: 047.60086 | P7: com muito "gengibre" | R7: =VLOOKUP(A7,comp!A:F,2,FALSE) -> 18.718462 | S7: =VLOOKUP(A7,comp!A:F,3,FALSE) -> 62.946466 | T7: =VLOOKUP(A7,comp!A:F,4,FALSE) -> 10.261326 | U7: =VLOOKUP(A7,comp!A:F,5,FALSE) -> 7.932794 | V7: =VLOOKUP(A7,comp!A:F,6,FALSE) -> 0.064838046 | W7: =VLOOKUP(A7,ndvi_vegnativa!A:F,2,FALSE) -> 0.7741789 | X7: =VLOOKUP(A7,ndvi_cana!A:F,2,FALSE) -> 0.58468119 | Y7: =VLOOKUP(A7,fragmentos!A:F,2,FALSE) -> 154.97493
A8: P009 | B8: C1 | C8: 059031067 | D8: 1A | E8: 43327 | F8: 0.72013889 | G8: 99 | H8: 43327 | I8: 0.64236111 | J8: 85 | K8: 11 | L8: app | M8: 25 | N8: 21.20505 | O8: 048.20357 | P8: app riparia em regeneracao / antiga plantacao de eucalipto / solo encharcado / nascente proxima | R8: =VLOOKUP(A8,comp!A:F,2,FALSE) -> 19.082786 | S8: =VLOOKUP(A8,comp!A:F,3,FALSE) -> 71.826817 | T8: =VLOOKUP(A8,comp!A:F,4,FALSE) -> 1.801167 | U8: =VLOOKUP(A8,comp!A:F,5,FALSE) -> 0.28187276 | V8: =VLOOKUP(A8,comp!A:F,6,FALSE) -> 4.3746653 | W8: =VLOOKUP(A8,ndvi_vegnativa!A:F,2,FALSE) -> 0.64742379 | X8: =VLOOKUP(A8,ndvi_cana!A:F,2,FALSE) -> 0.58366613 | Y8: =VLOOKUP(A8,fragmentos!A:F,2,FALSE) -> 158.05964
A9: P009 | B9: C2 | C9: 059028604 | D9: 3A | E9: 43327 | F9: 0.74375 | G9: 93 | H9: 43327 | I9: 0.65625 | J9: 73 | K9: 197 | L9: app | M9: 20 | N9: 21.20436 | O9: 048.19925 | P9: app degradada com eucaliptos / riacho perto | Q9: visualizacao macaco prego / carcaca de porco domestico | R9: =VLOOKUP(A9,comp!A:F,2,FALSE) -> 19.082786 | S9: =VLOOKUP(A9,comp!A:F,3,FALSE) -> 71.826817 | T9: =VLOOKUP(A9,comp!A:F,4,FALSE) -> 1.801167 | U9: =VLOOKUP(A9,comp!A:F,5,FALSE) -> 0.28187276 | V9: =VLOOKUP(A9,comp!A:F,6,FALSE) -> 4.3746653 | W9: =VLOOKUP(A9,ndvi_vegnativa!A:F,2,FALSE) -> 0.64742379 | X9: =VLOOKUP(A9,ndvi_cana!A:F,2,FALSE) -> 0.58366613 | Y9: =VLOOKUP(A9,fragmentos!A:F,2,FALSE) -> 158.05964
A10: P009 | B10: C3 | C10: 059028607 | D10: 17A | E10: 43327 | F10: 0.75763889 | G10: 87 | H10: 43327 | I10: 0.67777778 | J10: 84 | K10: 108 | L10: app | M10: 4 | N10: 21.20538 | O10: 048.19288 | P10: app riparia degradada / muito bambu / agua nas imediacoes | R10: =VLOOKUP(A10,comp!A:F,2,FALSE) -> 19.082786 | S10: =VLOOKUP(A10,comp!A:F,3,FALSE) -> 71.826817 | T10: =VLOOKUP(A10,comp!A:F,4,FALSE) -> 1.801167 | U10: =VLOOKUP(A10,comp!A:F,5,FALSE) -> 0.28187276 | V10: =VLOOKUP(A10,comp!A:F,6,FALSE) -> 4.3746653 | W10: =VLOOKUP(A10,ndvi_vegnativa!A:F,2,FALSE) -> 0.64742379 | X10: =VLOOKUP(A10,ndvi_cana!A:F,2,FALSE) -> 0.58366613 | Y10: =VLOOKUP(A10,fragmentos!A:F,2,FALSE) -> 158.05964
A11: P010 | B11: C1 | C11: 059.028592 | D11: 1A | E11: 42891 | F11: 0.53333333 | G11: 99 | H11: 42919 | I11: 0.38333333 | J11: 81 | K11: 102 | L11: eucalipto | M11: 20 | N11: 21.60966 | O11: 048.20454 | P11: formigueiro com sauva no pé da camera / prop. Jaiminho | R11: =VLOOKUP(A11,comp!A:F,2,FALSE) -> 56.627864 | S11: =VLOOKUP(A11,comp!A:F,3,FALSE) -> 33.135094 | T11: =VLOOKUP(A11,comp!A:F,4,FALSE) -> 4.881761 | U11: =VLOOKUP(A11,comp!A:F,5,FALSE) -> 3.2695397 | V11: =VLOOKUP(A11,comp!A:F,6,FALSE) -> 0.13810987 | W11: =VLOOKUP(A11,ndvi_vegnativa!A:F,2,FALSE) -> 0.79797654 | X11: =VLOOKUP(A11,ndvi_cana!A:F,2,FALSE) -> 0.56314177 | Y11: =VLOOKUP(A11,fragmentos!A:F,2,FALSE) -> 171.47332
A12: P010 | B12: C2 | C12: 059.031067 | D12: 2A | E12: 42891 | F12: 0.57013889 | G12: 97 | H12: 42919 | I12: 0.40347222 | J12: 79 | K12: 112 | L12: app/eucalipto | M12: 14 | N12: 21.59892 | O12: 048.21135 | R12: =VLOOKUP(A12,comp!A:F,2,FALSE) -> 56.627864 | S12: =VLOOKUP(A12,comp!A:F,3,FALSE) -> 33.135094 | T12: =VLOOKUP(A12,comp!A:F,4,FALSE) -> 4.881761 | U12: =VLOOKUP(A12,comp!A:F,5,FALSE) -> 3.2695397 | V12: =VLOOKUP(A12,comp!A:F,6,FALSE) -> 0.13810987 | W12: =VLOOKUP(A12,ndvi_vegnativa!A:F,2,FALSE) -> 0.79797654 | X12: =VLOOKUP(A12,ndvi_cana!A:F,2,FALSE) -> 0.56314177 | Y12: =VLOOKUP(A12,fragmentos!A:F,2,FALSE) -> 171.47332
A13: P010 | B13: C3 | C13: 059.028599 | D13: 3A | E13: 42891 | F13: 0.39513889 | G13: 99 | H13: 42919 | I13: 0.40833333 | J13: 82 | K13: 114 | L13: app | M13: 9 | N13: 21.59838 | O13: 048.21051 | P13: ao lado de plantio de eucalipto / largura do curso d'água = 8m | R13: =VLOOKUP(A13,comp!A:F,2,FALSE) -> 56.627864 | S13: =VLOOKUP(A13,comp!A:F,3,FALSE) -> 33.135094 | T13: =VLOOKUP(A13,comp!A:F,4,FALSE) -> 4.881761 | U13: =VLOOKUP(A13,comp!A:F,5,FALSE) -> 3.2695397 | V13: =VLOOKUP(A13,comp!A:F,6,FALSE) -> 0.13810987 | W13: =VLOOKUP(A13,ndvi_vegnativa!A:F,2,FALSE) -> 0.79797654 | X13: =VLOOKUP(A13,ndvi_cana!A:F,2,FALSE) -> 0.56314177 | Y13: =VLOOKUP(A13,fragmentos!A:F,2,FALSE) -> 171.47332
A14: P011 | B14: C1 | C14: 059.028608 | D14: 2B | E14: 43223 | F14: 0.37152778 | G14: 97 | H14: 43263 | I14: 0.67916667 | J14: 80 | K14: 118 | L14: mesofila | M14: 7.5 | N14: 20.83016 | O14: 047.53245 | P14: mata mesofila semidecidual degradada / emergentes 15-20m / dossel descontinuo / muito cipo | Q14: escarificaçção de sagui | R14: =VLOOKUP(A14,comp!A:F,2,FALSE) -> 29.41276 | S14: =VLOOKUP(A14,comp!A:F,3,FALSE) -> 49.925291 | T14: =VLOOKUP(A14,comp!A:F,4,FALSE) -> 15.914409 | U14: =VLOOKUP(A14,comp!A:F,5,FALSE) -> 4.2175298 | V14: =VLOOKUP(A14,comp!A:F,6,FALSE) -> 0.36085817 | W14: =VLOOKUP(A14,ndvi_vegnativa!A:F,2,FALSE) -> 0.79507342 | X14: =VLOOKUP(A14,ndvi_cana!A:F,2,FALSE) -> 0.66780353 | Y14: =VLOOKUP(A14,fragmentos!A:F,2,FALSE) -> 137.03222
A15: P011 | B15: C2 | C15: 059.031068 | D15: 4B | E15: 43223 | F15: 0.46319444 | G15: 94 | H15: 43263 | I15: 0.70763889 | J15: 63 | K15: 1971 | L15: app | M15: 7 | N15: 20.82955 | O15: 047.52499 | P15: mata ciliar em regeneração / AF ao lado do rio com 8-10m de largura | Q15: rastro de boi | R15: =VLOOKUP(A15,comp!A:F,2,FALSE) -> 29.41276 | S15: =VLOOKUP(A15,comp!A:F,3,FALSE) -> 49.925291 | T15: =VLOOKUP(A15,comp!A:F,4,FALSE) -> 15.914409 | U15: =VLOOKUP(A15,comp!A:F,5,FALSE) -> 4.2175298 | V15: =VLOOKUP(A15,comp!A:F,6,FALSE) -> 0.36085817 | W15: =VLOOKUP(A15,ndvi_vegnativa!A:F,2,FALSE) -> 0.79507342 | X15: =VLOOKUP(A15,ndvi_cana!A:F,2,FALSE) -> 0.66780353 | Y15: =VLOOKUP(A15,fragmentos!A:F,2,FALSE) -> 137.03222
A16: P011 | B16: C3 | C16: 059.028599 | D16: 1B | E16: 43223 | F16: 0.60416667 | G16: 95 | H16: 43263 | I16: 0.68819444 | J16: 80 | K16: 238 | L16: mesofila | M16: 7 | N16: 20.83284 | O16: 047.53115 | P16: emergentes 19m / broto de cafe / dossel descontinuo | R16: =VLOOKUP(A16,comp!A:F,2,FALSE) -> 29.41276 | S16: =VLOOKUP(A16,comp!A:F,3,FALSE) -> 49.925291 | T16: =VLOOKUP(A16,comp!A:F,4,FALSE) -> 15.914409 | U16: =VLOOKUP(A16,comp!A:F,5,FALSE) -> 4.2175298 | V16: =VLOOKUP(A16,comp!A:F,6,FALSE) -> 0.36085817 | W16: =VLOOKUP(A16,ndvi_vegnativa!A:F,2,FALSE) -> 0.79507342 | X16: =VLOOKUP(A16,ndvi_cana!A:F,2,FALSE) -> 0.66780353 | Y16: =VLOOKUP(A16,fragmentos!A:F,2,FALSE) -> 137.03222
A17: P013 | B17: C1 | C17: 059.028605 | D17: 5A | E17: 43195 | F17: 0.45763889 | G17: 99 | H17: 43228 | I17: 0.675 | J17: 85 | K17: 168 | L17: cerradao | M17: 8 | N17: 20.68538 | O17: 047.18901 | P17: cerradao topo de morro com caraguatá e boi / emergentes 15m | Q17: rastro de boi | R17: =VLOOKUP(A17,comp!A:F,2,FALSE) -> 55.055515 | S17: =VLOOKUP(A17,comp!A:F,3,FALSE) -> 8.0369723 | T17: =VLOOKUP(A17,comp!A:F,4,FALSE) -> 12.824776 | U17: =VLOOKUP(A17,comp!A:F,5,FALSE) -> 22.772361 | V17: =VLOOKUP(A17,comp!A:F,6,FALSE) -> 0 | W17: =VLOOKUP(A17,ndvi_vegnativa!A:F,2,FALSE) -> 0.83003473 | X17: =VLOOKUP(A17,ndvi_cana!A:F,2,FALSE) -> 0.63405669 | Y17: =VLOOKUP(A17,fragmentos!A:F,2,FALSE) -> 149.96065
A18: P013 | B18: C2 | C18: 059.028591 | D18: 13A | E18: 43195 | F18: 0.56041667 | G18: 99 | H18: 43228 | I18: 0.66180556 | J18: 85 | K18: 191 | L18: mesofila | M18: 11 | N18: 20.67730 | O18: 047.18070 | P18: mesofila ao lado de cursa dágua / serrapilheira / degradado / descontinuo / trilha de boi / proximo a residencia | R18: =VLOOKUP(A18,comp!A:F,2,FALSE) -> 55.055515 | S18: =VLOOKUP(A18,comp!A:F,3,FALSE) -> 8.0369723 | T18: =VLOOKUP(A18,comp!A:F,4,FALSE) -> 12.824776 | U18: =VLOOKUP(A18,comp!A:F,5,FALSE) -> 22.772361 | V18: =VLOOKUP(A18,comp!A:F,6,FALSE) -> 0 | W18: =VLOOKUP(A18,ndvi_vegnativa!A:F,2,FALSE) -> 0.83003473 | X18: =VLOOKUP(A18,ndvi_cana!A:F,2,FALSE) -> 0.63405669 | Y18: =VLOOKUP(A18,fragmentos!A:F,2,FALSE) -> 149.96065
A19: P013 | B19: C3 | C19: 059.028592 | D19: 2A | E19: 43195 | F19: 0.64166667 | G19: 99 | H19: 43228 | I19: 0.69513889 | J19: 81 | K19: 177 | L19: mesofila | M19: 10 | N19: 20.67754 | O19: 047.19083 | P19: mesofila proxima de rio / parte degradada / dossel descontinuo / emergentes 20m / | Q19: boi / cavalo / cachorro | R19: =VLOOKUP(A19,comp!A:F,2,FALSE) -> 55.055515 | S19: =VLOOKUP(A19,comp!A:F,3,FALSE) -> 8.0369723 | T19: =VLOOKUP(A19,comp!A:F,4,FALSE) -> 12.824776 | U19: =VLOOKUP(A19,comp!A:F,5,FALSE) -> 22.772361 | V19: =VLOOKUP(A19,comp!A:F,6,FALSE) -> 0 | W19: =VLOOKUP(A19,ndvi_vegnativa!A:F,2,FALSE) -> 0.83003473 | X19: =VLOOKUP(A19,ndvi_cana!A:F,2,FALSE) -> 0.63405669 | Y19: =VLOOKUP(A19,fragmentos!A:F,2,FALSE) -> 149.96065
A20: P015 | B20: C1 | C20: 059.028604 | D20: 12B | E20: 43222 | F20: 0.35208333 | G20: 99 | H20: 43262 | I20: 0.70833333 | J20: 79 | K20: 258 | L20: mesofila | M20: 14 | N20: 20.92410 | O20: 047.48651 | P20: semidecidua muito degradada / dossel descontinuo | Q20: toca de tatu | R20: =VLOOKUP(A20,comp!A:F,2,FALSE) -> 18.511526 | S20: =VLOOKUP(A20,comp!A:F,3,FALSE) -> 71.887505 | T20: =VLOOKUP(A20,comp!A:F,4,FALSE) -> 9.1444513 | U20: =VLOOKUP(A20,comp!A:F,5,FALSE) -> 0.26207518 | V20: =VLOOKUP(A20,comp!A:F,6,FALSE) -> 0.095812433 | W20: =VLOOKUP(A20,ndvi_vegnativa!A:F,2,FALSE) -> 0.76979756 | X20: =VLOOKUP(A20,ndvi_cana!A:F,2,FALSE) -> 0.59983377 | Y20: =VLOOKUP(A20,fragmentos!A:F,2,FALSE) -> 162.04573
A21: P015 | B21: C2 | C21: 059.028590 | D21: 10B | E21: 43222 | F21: 0.38472222 | G21: 99 | H21: 43262 | I21: 0.72013889 | J21: 80 | K21: 158 | L21: app | M21: 14 | N21: 20.92756 | O21: 047.48679 | P21: app riparia com vegetacao de brejo/varzea / dossel descontinuo | R21: =VLOOKUP(A21,comp!A:F,2,FALSE) -> 18.511526 | S21: =VLOOKUP(A21,comp!A:F,3,FALSE) -> 71.887505 | T21: =VLOOKUP(A21,comp!A:F,4,FALSE) -> 9.1444513 | U21: =VLOOKUP(A21,comp!A:F,5,FALSE) -> 0.26207518 | V21: =VLOOKUP(A21,comp!A:F,6,FALSE) -> 0.095812433 | W21: =VLOOKUP(A21,ndvi_vegnativa!A:F,2,FALSE) -> 0.76979756 | X21: =VLOOKUP(A21,ndvi_cana!A:F,2,FALSE) -> 0.59983377 | Y21: =VLOOKUP(A21,fragmentos!A:F,2,FALSE) -> 162.04573
A22: P015 | B22: C3 | C22: 059.031069 | D22: 17B | E22: 43222 | F22: 0.46458333 | G22: 99 | H22: 43262 | I22: 0.69722222 | J22: 87 | K22: 266 | L22: reflorestamento | M22: 7.5 | N22: 20.92194 | O22: 047.47497 | P22: reflorestamento app | Q22: visualização e fezes veado-catingueiro | R22: =VLOOKUP(A22,comp!A:F,2,FALSE) -> 18.511526 | S22: =VLOOKUP(A22,comp!A:F,3,FALSE) -> 71.887505 | T22: =VLOOKUP(A22,comp!A:F,4,FALSE) -> 9.1444513 | U22: =VLOOKUP(A22,comp!A:F,5,FALSE) -> 0.26207518 | V22: =VLOOKUP(A22,comp!A:F,6,FALSE) -> 0.095812433 | W22: =VLOOKUP(A22,ndvi_vegnativa!A:F,2,FALSE) -> 0.76979756 | X22: =VLOOKUP(A22,ndvi_cana!A:F,2,FALSE) -> 0.59983377 | Y22: =VLOOKUP(A22,fragmentos!A:F,2,FALSE) -> 162.04573
A23: P020 | B23: C1 | C23: 059.028608 | D23: 8A | E23: 42948 | F23: 0.46944444 | G23: 99 | H23: 42978 | I23: 0.34097222 | J23: 69 | K23: 528 | L23: app | M23: 8 | N23: 20.82733 | O23: 048.47550 | P23: mata alagada / solo tipo brejo / em regeneracao | Q23: cranio e pegadas de porco | R23: =VLOOKUP(A23,comp!A:F,2,FALSE) -> 28.731228 | S23: =VLOOKUP(A23,comp!A:F,3,FALSE) -> 63.021611 | T23: =VLOOKUP(A23,comp!A:F,4,FALSE) -> 5.221042 | U23: =VLOOKUP(A23,comp!A:F,5,FALSE) -> 0.38601336 | V23: =VLOOKUP(A23,comp!A:F,6,FALSE) -> 2.507678 | W23: =VLOOKUP(A23,ndvi_vegnativa!A:F,2,FALSE) -> 0.7769241 | X23: =VLOOKUP(A23,ndvi_cana!A:F,2,FALSE) -> 0.51090354 | Y23: =VLOOKUP(A23,fragmentos!A:F,2,FALSE) -> 386.30962
A24: P020 | B24: C2 | C24: 059.028607 | D24: 9A | E24: 42948 | F24: 0.51666667 | G24: 93 | H24: 42978 | I24: 0.32916667 | J24: 89 | K24: 426 | L24: transicao | M24: 9 | N24: 20.82887 | O24: 048.47620 | P24: transição de mata alagada para cerradao / um pouco mais seco | Q24: chafurdado de javali | R24: =VLOOKUP(A24,comp!A:F,2,FALSE) -> 28.731228 | S24: =VLOOKUP(A24,comp!A:F,3,FALSE) -> 63.021611 | T24: =VLOOKUP(A24,comp!A:F,4,FALSE) -> 5.221042 | U24: =VLOOKUP(A24,comp!A:F,5,FALSE) -> 0.38601336 | V24: =VLOOKUP(A24,comp!A:F,6,FALSE) -> 2.507678 | W24: =VLOOKUP(A24,ndvi_vegnativa!A:F,2,FALSE) -> 0.7769241 | X24: =VLOOKUP(A24,ndvi_cana!A:F,2,FALSE) -> 0.51090354 | Y24: =VLOOKUP(A24,fragmentos!A:F,2,FALSE) -> 386.30962
A25: P020 | B25: C3 | C25: 059.028604 | D25: 7A | E25: 42948 | F25: 0.66111111 | G25: 90 | H25: 42978 | I25: 0.31666667 | J25: 74 | K25: 126 | L25: reflorestamento | M25: 12 | N25: 20.81842 | O25: 048.48124 | P25: linhas de plantio | R25: =VLOOKUP(A25,comp!A:F,2,FALSE) -> 28.731228 | S25: =VLOOKUP(A25,comp!A:F,3,FALSE) -> 63.021611 | T25: =VLOOKUP(A25,comp!A:F,4,FALSE) -> 5.221042 | U25: =VLOOKUP(A25,comp!A:F,5,FALSE) -> 0.38601336 | V25: =VLOOKUP(A25,comp!A:F,6,FALSE) -> 2.507678 | W25: =VLOOKUP(A25,ndvi_vegnativa!A:F,2,FALSE) -> 0.7769241 | X25: =VLOOKUP(A25,ndvi_cana!A:F,2,FALSE) -> 0.51090354 | Y25: =VLOOKUP(A25,fragmentos!A:F,2,FALSE) -> 386.30962
A26: P021 | B26: C1 | C26: 059028591 | D26: 12B | E26: 43356 | F26: 0.39513889 | G26: 97 | H26: 43396 | I26: 0.61180556 | J26: 83 | K26: 345 | L26: app | M26: 6 | N26: 20.42632 | O26: 048.07698 | P26: solo escuro e molhado | R26: =VLOOKUP(A26,comp!A:F,2,FALSE) -> 37.63129 | S26: =VLOOKUP(A26,comp!A:F,3,FALSE) -> 52.220314 | T26: =VLOOKUP(A26,comp!A:F,4,FALSE) -> 5.9780925 | U26: =VLOOKUP(A26,comp!A:F,5,FALSE) -> 2.9116098 | V26: =VLOOKUP(A26,comp!A:F,6,FALSE) -> 0.6532819 | W26: =VLOOKUP(A26,ndvi_vegnativa!A:F,2,FALSE) -> 0.82636901 | X26: =VLOOKUP(A26,ndvi_cana!A:F,2,FALSE) -> 0.65787421 | Y26: =VLOOKUP(A26,fragmentos!A:F,2,FALSE) -> 362.02819
A27: P021 | B27: C2 | C27: 059028604 | D27: 18B | E27: 43356 | F27: 0.47708333 | G27: 94 | H27: 43396 | I27: 0.625 | J27: 84 | K27: 234 | L27: app | M27: 20 | N27: 20.42219 | O27: 048.08419 | P27: ao lado de córrego e com várias minas, sensor funcionando lentamente | Q27: vocalização de sagui e troncos sujos de javali | R27: =VLOOKUP(A27,comp!A:F,2,FALSE) -> 37.63129 | S27: =VLOOKUP(A27,comp!A:F,3,FALSE) -> 52.220314 | T27: =VLOOKUP(A27,comp!A:F,4,FALSE) -> 5.9780925 | U27: =VLOOKUP(A27,comp!A:F,5,FALSE) -> 2.9116098 | V27: =VLOOKUP(A27,comp!A:F,6,FALSE) -> 0.6532819 | W27: =VLOOKUP(A27,ndvi_vegnativa!A:F,2,FALSE) -> 0.82636901 | X27: =VLOOKUP(A27,ndvi_cana!A:F,2,FALSE) -> 0.65787421 | Y27: =VLOOKUP(A27,fragmentos!A:F,2,FALSE) -> 362.02819
A28: P021 | B28: C3 | C28: 059028590 | D28: 8B | E28: 43356 | F28: 0.51527778 | G28: 89 | H28: 43396 | I28: 0.63888889 | J28: 57 | K28: 362 | L28: app | M28: 20 | N28: 20.42034 | O28: 048.08577 | P28: próximo córrego | R28: =VLOOKUP(A28,comp!A:F,2,FALSE) -> 37.63129 | S28: =VLOOKUP(A28,comp!A:F,3,FALSE) -> 52.220314 | T28: =VLOOKUP(A28,comp!A:F,4,FALSE) -> 5.9780925 | U28: =VLOOKUP(A28,comp!A:F,5,FALSE) -> 2.9116098 | V28: =VLOOKUP(A28,comp!A:F,6,FALSE) -> 0.6532819 | W28: =VLOOKUP(A28,ndvi_vegnativa!A:F,2,FALSE) -> 0.82636901 | X28: =VLOOKUP(A28,ndvi_cana!A:F,2,FALSE) -> 0.65787421 | Y28: =VLOOKUP(A28,fragmentos!A:F,2,FALSE) -> 362.02819
A29: P027 | B29: C1 | C29: 059.028604 | D29: 16B | E29: 42920 | F29: 0.55069444 | G29: 90 | H29: 42948 | I29: 0.31944444 | J29: 68 | K29: 120 | L29: app | M29: 17 | N29: 21.06772 | O29: 048.17506 | P29: em regeneracao | R29: =VLOOKUP(A29,comp!A:F,2,FALSE) -> 14.183018 | S29: =VLOOKUP(A29,comp!A:F,3,FALSE) -> 69.181326 | T29: =VLOOKUP(A29,comp!A:F,4,FALSE) -> 3.1997068 | U29: =VLOOKUP(A29,comp!A:F,5,FALSE) -> 2.8219441 | V29: =VLOOKUP(A29,comp!A:F,6,FALSE) -> 5.9060668 | W29: =VLOOKUP(A29,ndvi_vegnativa!A:F,2,FALSE) -> 0.68702282 | X29: =VLOOKUP(A29,ndvi_cana!A:F,2,FALSE) -> 0.54530585 | Y29: =VLOOKUP(A29,fragmentos!A:F,2,FALSE) -> 206.10476
A30: P027 | B30: C2 | C30: 059.028608 | D30: 17B | E30: 42920 | F30: 0.56666667 | G30: 70 | H30: 42948 | I30: 0.325 | J30: 45 | K30: 77 | L30: app | M30: 17 | N30: 21.06718 | O30: 048.17568 | P30: em regeneracao | Q30: fezes de bugio | R30: =VLOOKUP(A30,comp!A:F,2,FALSE) -> 14.183018 | S30: =VLOOKUP(A30,comp!A:F,3,FALSE) -> 69.181326 | T30: =VLOOKUP(A30,comp!A:F,4,FALSE) -> 3.1997068 | U30: =VLOOKUP(A30,comp!A:F,5,FALSE) -> 2.8219441 | V30: =VLOOKUP(A30,comp!A:F,6,FALSE) -> 5.9060668 | W30: =VLOOKUP(A30,ndvi_vegnativa!A:F,2,FALSE) -> 0.68702282 | X30: =VLOOKUP(A30,ndvi_cana!A:F,2,FALSE) -> 0.54530585 | Y30: =VLOOKUP(A30,fragmentos!A:F,2,FALSE) -> 206.10476
A31: P027 | B31: C3 | C31: 059.028607 | D31: 15B | E31: 42920 | F31: 0.58472222 | G31: 93 | H31: 42948 | I31: 0.33472222 | J31: 78 | K31: 125 | L31: app | M31: 7 | N31: 21.06739 | O31: 048.17810 | P31: em regeneracao | Q31: toca de tatu | R31: =VLOOKUP(A31,comp!A:F,2,FALSE) -> 14.183018 | S31: =VLOOKUP(A31,comp!A:F,3,FALSE) -> 69.181326 | T31: =VLOOKUP(A31,comp!A:F,4,FALSE) -> 3.1997068 | U31: =VLOOKUP(A31,comp!A:F,5,FALSE) -> 2.8219441 | V31: =VLOOKUP(A31,comp!A:F,6,FALSE) -> 5.9060668 | W31: =VLOOKUP(A31,ndvi_vegnativa!A:F,2,FALSE) -> 0.68702282 | X31: =VLOOKUP(A31,ndvi_cana!A:F,2,FALSE) -> 0.54530585 | Y31: =VLOOKUP(A31,fragmentos!A:F,2,FALSE) -> 206.10476
A32: P034 | B32: C1 | C32: 059.028606 | D32: 17A | E32: 42950 | F32: 0.45347222 | G32: 95 | H32: 42982 | I32: 0.31319444 | J32: 64 | K32: 201 | L32: mesofila | M32: 13.5 | N32: 21.52393 | O32: 048.55500 | P32: degradada / muita liana e dossel descontínuo | R32: =VLOOKUP(A32,comp!A:F,2,FALSE) -> 22.419428 | S32: =VLOOKUP(A32,comp!A:F,3,FALSE) -> 66.291977 | T32: =VLOOKUP(A32,comp!A:F,4,FALSE) -> 8.3502366 | U32: =VLOOKUP(A32,comp!A:F,5,FALSE) -> 1.9579671 | V32: =VLOOKUP(A32,comp!A:F,6,FALSE) -> 0.40004508 | W32: =VLOOKUP(A32,ndvi_vegnativa!A:F,2,FALSE) -> 0.83198154 | X32: =VLOOKUP(A32,ndvi_cana!A:F,2,FALSE) -> 0.53925551 | Y32: =VLOOKUP(A32,fragmentos!A:F,2,FALSE) -> 198.1737
A33: P034 | B33: C2 | C33: 059.028596 | D33: 12A | E33: 42950 | F33: 0.55833333 | G33: 99 | H33: 42982 | I33: 0.32708333 | J33: 81 | K33: 580 | L33: mesofila | M33: 9 | N33: 21.52535 | O33: 048.55531 | P33: palmito | R33: =VLOOKUP(A33,comp!A:F,2,FALSE) -> 22.419428 | S33: =VLOOKUP(A33,comp!A:F,3,FALSE) -> 66.291977 | T33: =VLOOKUP(A33,comp!A:F,4,FALSE) -> 8.3502366 | U33: =VLOOKUP(A33,comp!A:F,5,FALSE) -> 1.9579671 | V33: =VLOOKUP(A33,comp!A:F,6,FALSE) -> 0.40004508 | W33: =VLOOKUP(A33,ndvi_vegnativa!A:F,2,FALSE) -> 0.83198154 | X33: =VLOOKUP(A33,ndvi_cana!A:F,2,FALSE) -> 0.53925551 | Y33: =VLOOKUP(A33,fragmentos!A:F,2,FALSE) -> 198.1737
A34: P034 | B34: C3 | C34: 059.028602 | D34: 4A | E34: 42950 | F34: 0.61041667 | G34: 93 | H34: 42982 | I34: 0.30625 | J34: 56 | K34: 361 | L34: mesofila | M34: 12 | N34: 21.52258 | O34: 048.54712 | P34: degradada / emergentes de 20m / dossel descontínuo / muitas lianas | R34: =VLOOKUP(A34,comp!A:F,2,FALSE) -> 22.419428 | S34: =VLOOKUP(A34,comp!A:F,3,FALSE) -> 66.291977 | T34: =VLOOKUP(A34,comp!A:F,4,FALSE) -> 8.3502366 | U34: =VLOOKUP(A34,comp!A:F,5,FALSE) -> 1.9579671 | V34: =VLOOKUP(A34,comp!A:F,6,FALSE) -> 0.40004508 | W34: =VLOOKUP(A34,ndvi_vegnativa!A:F,2,FALSE) -> 0.83198154 | X34: =VLOOKUP(A34,ndvi_cana!A:F,2,FALSE) -> 0.53925551 | Y34: =VLOOKUP(A34,fragmentos!A:F,2,FALSE) -> 198.1737
A35: P036 | B35: C1 | C35: 059031066 | D35: 3B | E35: 43357 | F35: 0.46597222 | G35: 97 | H35: 43396 | I35: 0.40486111 | J35: 83 | K35: 603 | L35: decidua | M35: 20 | N35: 20.65414 | O35: 048.68321 | P35: alto de morro, predominio de angicos, dossel descontínuo, marcas de fogo | R35: =VLOOKUP(A35,comp!A:F,2,FALSE) -> 25.195098 | S35: =VLOOKUP(A35,comp!A:F,3,FALSE) -> 51.097338 | T35: =VLOOKUP(A35,comp!A:F,4,FALSE) -> 17.698267 | U35: =VLOOKUP(A35,comp!A:F,5,FALSE) -> 5.431751 | V35: =VLOOKUP(A35,comp!A:F,6,FALSE) -> 0.17467249 | W35: =VLOOKUP(A35,ndvi_vegnativa!A:F,2,FALSE) -> 0.82827918 | X35: =VLOOKUP(A35,ndvi_cana!A:F,2,FALSE) -> 0.51138194 | Y35: =VLOOKUP(A35,fragmentos!A:F,2,FALSE) -> 178.41672
A36: P036 | B36: C2 | C36: 059031067 | D36: 7B | E36: 43357 | F36: 0.49583333 | G36: 95 | H36: 43396 | I36: 0.38541667 | J36: 84 | K36: 645 | L36: app | M36: 20 | N36: 20.65731 | O36: 048.68097 | P36: córrego estreito e muito limpo perto da câmera, com peixinhos, figueira enorme próxima | Q36: pisados de javali | R36: =VLOOKUP(A36,comp!A:F,2,FALSE) -> 25.195098 | S36: =VLOOKUP(A36,comp!A:F,3,FALSE) -> 51.097338 | T36: =VLOOKUP(A36,comp!A:F,4,FALSE) -> 17.698267 | U36: =VLOOKUP(A36,comp!A:F,5,FALSE) -> 5.431751 | V36: =VLOOKUP(A36,comp!A:F,6,FALSE) -> 0.17467249 | W36: =VLOOKUP(A36,ndvi_vegnativa!A:F,2,FALSE) -> 0.82827918 | X36: =VLOOKUP(A36,ndvi_cana!A:F,2,FALSE) -> 0.51138194 | Y36: =VLOOKUP(A36,fragmentos!A:F,2,FALSE) -> 178.41672
A37: P036 | B37: C3 | C37: 059026608 | D37: 15B | E37: 43357 | F37: 0.62708333 | G37: 95 | H37: 43396 | I37: 0.33819444 | J37: 83 | K37: 561 | L37: app | M37: 20 | N37: 20.65704 | O37: 048.67402 | P37: ao lado de seringal, peryo de riacho, cortaiuva | Q37: marca de javali em árvore | R37: =VLOOKUP(A37,comp!A:F,2,FALSE) -> 25.195098 | S37: =VLOOKUP(A37,comp!A:F,3,FALSE) -> 51.097338 | T37: =VLOOKUP(A37,comp!A:F,4,FALSE) -> 17.698267 | U37: =VLOOKUP(A37,comp!A:F,5,FALSE) -> 5.431751 | V37: =VLOOKUP(A37,comp!A:F,6,FALSE) -> 0.17467249 | W37: =VLOOKUP(A37,ndvi_vegnativa!A:F,2,FALSE) -> 0.82827918 | X37: =VLOOKUP(A37,ndvi_cana!A:F,2,FALSE) -> 0.51138194 | Y37: =VLOOKUP(A37,fragmentos!A:F,2,FALSE) -> 178.41672
A38: P040 | B38: C1 | C38: 059.031067 | D38: 11B | E38: 42977 | F38: 0.53819444 | G38: 90 | H38: 43006 | I38: 0.32222222 | J38: 79 | K38: 231 | L38: app | M38: 10 | N38: 21.20556 | O38: 048.41809 | P38: cerradao / proximo a curso dagua / sub-bosque tipico de areas alagadas | R38: =VLOOKUP(A38,comp!A:F,2,FALSE) -> 25.406046 | S38: =VLOOKUP(A38,comp!A:F,3,FALSE) -> 67.840627 | T38: =VLOOKUP(A38,comp!A:F,4,FALSE) -> 2.1063614 | U38: =VLOOKUP(A38,comp!A:F,5,FALSE) -> 3.502143 | V38: =VLOOKUP(A38,comp!A:F,6,FALSE) -> 0.64008572 | W38: =VLOOKUP(A38,ndvi_vegnativa!A:F,2,FALSE) -> 0.77238381 | X38: =VLOOKUP(A38,ndvi_cana!A:F,2,FALSE) -> 0.49292616 | Y38: =VLOOKUP(A38,fragmentos!A:F,2,FALSE) -> 316.73466
A39: P040 | B39: C2 | C39: 059.028592 | D39: 6B | E39: 42977 | F39: 0.6125 | G39: 83 | H39: 43006 | I39: 0.30833333 | J39: 62 | K39: 193 | L39: app | M39: 15 | N39: 21.20635 | O39: 048.41917 | P39: cerradao / proximo a curso dagua / dossel descontinuo | R39: =VLOOKUP(A39,comp!A:F,2,FALSE) -> 25.406046 | S39: =VLOOKUP(A39,comp!A:F,3,FALSE) -> 67.840627 | T39: =VLOOKUP(A39,comp!A:F,4,FALSE) -> 2.1063614 | U39: =VLOOKUP(A39,comp!A:F,5,FALSE) -> 3.502143 | V39: =VLOOKUP(A39,comp!A:F,6,FALSE) -> 0.64008572 | W39: =VLOOKUP(A39,ndvi_vegnativa!A:F,2,FALSE) -> 0.77238381 | X39: =VLOOKUP(A39,ndvi_cana!A:F,2,FALSE) -> 0.49292616 | Y39: =VLOOKUP(A39,fragmentos!A:F,2,FALSE) -> 316.73466
A40: P040 | B40: C3 | C40: 059.028598 | D40: 15B | E40: 42977 | F40: 0.70763889 | G40: 95 | H40: 43006 | I40: 0.29930556 | J40: 79 | K40: 170 | L40: reflorestamento | M40: 5 | N40: 21.20720 | O40: 048.41933 | P40: borda de reflorestamento em contato com varzea | R40: =VLOOKUP(A40,comp!A:F,2,FALSE) -> 25.406046 | S40: =VLOOKUP(A40,comp!A:F,3,FALSE) -> 67.840627 | T40: =VLOOKUP(A40,comp!A:F,4,FALSE) -> 2.1063614 | U40: =VLOOKUP(A40,comp!A:F,5,FALSE) -> 3.502143 | V40: =VLOOKUP(A40,comp!A:F,6,FALSE) -> 0.64008572 | W40: =VLOOKUP(A40,ndvi_vegnativa!A:F,2,FALSE) -> 0.77238381 | X40: =VLOOKUP(A40,ndvi_cana!A:F,2,FALSE) -> 0.49292616 | Y40: =VLOOKUP(A40,fragmentos!A:F,2,FALSE) -> 316.73466
...

Sheet comp
A1: ID | B1: agricultura_3000m | C1: cana_300m | D1: floresta_3000m | E1: pastagem_3000m | F1: veg_herb_arb_3000m | G1: ndvi_vegnativa_3000m
A2: p003 | B2: 29.234672 | C2: 58.883721 | D2: 9.5870331 | E2: 1.9281184 | F2: 0.10147992
A3: p006 | B3: 18.718462 | C3: 62.946466 | D3: 10.261326 | E3: 7.932794 | F3: 0.064838046
A4: p009 | B4: 19.082786 | C4: 71.826817 | D4: 1.801167 | E4: 0.28187276 | F4: 4.3746653
A5: p010 | B5: 56.627864 | C5: 33.135094 | D5: 4.881761 | E5: 3.2695397 | F5: 0.13810987
A6: p011 | B6: 29.41276 | C6: 49.925291 | D6: 15.914409 | E6: 4.2175298 | F6: 0.36085817
A7: p013 | B7: 55.055515 | C7: 8.0369723 | D7: 12.824776 | E7: 22.772361 | F7: 0
A8: p015 | B8: 18.511526 | C8: 71.887505 | D8: 9.1444513 | E8: 0.26207518 | F8: 0.095812433
A9: p020 | B9: 28.731228 | C9: 63.021611 | D9: 5.221042 | E9: 0.38601336 | F9: 2.507678
A10: p021 | B10: 37.63129 | C10: 52.220314 | D10: 5.9780925 | E10: 2.9116098 | F10: 0.6532819
A11: p027 | B11: 14.183018 | C11: 69.181326 | D11: 3.1997068 | E11: 2.8219441 | F11: 5.9060668
A12: p034 | B12: 22.419428 | C12: 66.291977 | D12: 8.3502366 | E12: 1.9579671 | F12: 0.40004508
A13: p036 | B13: 25.195098 | C13: 51.097338 | D13: 17.698267 | E13: 5.431751 | F13: 0.17467249
... A56: p151 | B56: 27.423581 | C56: 64.161149 | D56: 5.1077617 | E56: 2.6792506 | F56: 0.20566277

Sheet ndvi_vegnativa
A1: Código da Paisagem | B1: ndvi_vegnativa_3000m
A2: p003 | B2: 0.8295516
A3: p006 | B3: 0.7741789
A4: p009 | B4: 0.64742379
A5: p010 | B5: 0.79797654
A6: p011 | B6: 0.79507342
A7: p013 | B7: 0.83003473
A8: p015 | B8: 0.76979756
A9: p020 | B9: 0.7769241
A10: p021 | B10: 0.82636901
A11: p027 | B11: 0.68702282
A12: p034 | B12: 0.83198154
A13: p036 | B13: 0.82827918
... A56: p151 | B56: 0.79888114

Sheet ndvi_cana
A1: paisagem | B1: ndvi_cana_3000
A2: p003 | B2: 0.50019547
A3: p006 | B3: 0.58468119
A4: p009 | B4: 0.58366613
A5: p010 | B5: 0.56314177
A6: p011 | B6: 0.66780353
A7: p013 | B7: 0.63405669
A8: p015 | B8: 0.59983377
A9: p020 | B9: 0.51090354
A10: p021 | B10: 0.65787421
A11: p027 | B11: 0.54530585
A12: p034 | B12: 0.53925551
A13: p036 | B13: 0.51138194
... A56: p151 | B56: 0.52322599

Sheet fragmentos
A1: ID | B1: enn_mn_3000
A2: p003 | B2: 148.78106
A3: p006 | B3: 154.97493
A4: p009 | B4: 158.05964
A5: p010 | B5: 171.47332
A6: p011 | B6: 137.03222
A7: p013 | B7: 149.96065
A8: p015 | B8: 162.04573
A9: p020 | B9: 386.30962
A10: p021 | B10: 362.02819
A11: p027 | B11: 206.10476
A12: p034 | B12: 198.1737
A13: p036 | B13: 178.41672
... A47: p137 | B47: 118.21171
A48: p138
A49: p140 | B49: 177.41682
A50: p142 | B50: 116.04844
A51: p145 | B51: 144.59065
A52: p146 | B52: 96.409354
A53: p147 | B53: 70.864246
A54: p148 | B54: 127.92367
A55: p150 | B55: 186.4031
A56: p151 | B56: 221.77758
